Workbook

Sheet 4K
A1: Cost of a Financial Advisor
A2: my old advisors fee for AUM:
A3: 0 - 250,000 | B3: 0.0175
A4: 250,000 - 500,000 | B4: 0.015 | D4: They calculate their fee based on the daily closing value of your account, averaged over each month x the monthly portion of your annual rate.
A5: 500,000 - 1,000,000 | B5: 0.0125 | D5: Ex. 1. If daily average closing value of my account is $12,000 and the monthly fee is 0.146% (1.75%/12) then my fee for the month is (12,000 * 0.00146) = $17.52
A6: 1,000,000 - 2,000,000 | B6: 0.01 | D6: Ex. 2. If the following month I have $16,000 in my account, the fee for that month is 16,000 x 0.00146 = 23.36
A7: 2,000,000 - 6,000,000 | B7: 0.01 | D7: Ex. 3. What is the cost of all of this? You might think it is 17.52 + 23.36 = $40.88. You would be wrong! You've also lost out on the interest you would have gained on that 17.52 and 23.36. And the compounded interest on that interest. And the compounded interest on the interest of the interest. You get the idea. So what does that actually look like in real numbers?
A8: 6,000,000+ | B8: 0.0075
D10: Scenario 1 | AI10: Scenario 1 | AJ10: WITHOUT AN ADVISOR
D11: Assume I don't invest anything. It just sits there in a cash account. What would be the raw dollar cost of the financial advisor. (i.e. lost opportunity of compounding not realised) | AI11: Assume I don't invest anything. It just sits there in a cash account. What would be the raw dollar cost of the financial advisor. (i.e. lost opportunity of compounding not realised)
D12: Assume I save $4K/mo | AI12: Assume I save $4K/mo
D13: Y1 | E13: Y2 | F13: Y3 | G13: Y4 | H13: Y5 | I13: Y6 | J13: Y7 | K13: Y8 | L13: Y9 | M13: Y10 | N13: Y11 | O13: Y12 | P13: Y13 | Q13: Y14 | R13: Y15 | S13: Y16 | T13: Y17 | U13: Y18 | V13: Y19 | W13: Y20 | X13: Y21 | Y13: Y22 | Z13: Y23 | AA13: Y24 | AB13: Y25 | AC13: Y26 | AD13: Y27 | AE13: Y28 | AI13: Y1 | AJ13: Y2 | AK13: Y3 | AL13: Y4 | AM13: Y5 | AN13: Y6 | AO13: Y7 | AP13: Y8 | AQ13: Y9 | AR13: Y10 | AS13: Y11 | AT13: Y12 | AU13: Y13 | AV13: Y14 | AW13: Y15 | AX13: Y16 | AY13: Y17 | AZ13: Y18 | BA13: Y19 | BB13: Y20 | BC13: Y21 | BD13: Y22 | BE13: Y23 | BF13: Y24 | BG13: Y25 | BH13: Y26 | BI13: Y27 | BJ13: Y28
D14: 0 | AI14: 0
C15: J | D15: =(D14+4000)-(0.00146*(D14+4000)) -> 3994.16 | E15: =(D26+4000)-(0.00146*(D26+4000)) -> 51471.651 | F15: =(E26+4000)-(0.00146*(E26+4000)) -> 98123.984 | G15: =(F26+4000)-(0.00146*(F26+4000)) -> 143965.5 | H15: =(G26+4000)-(0.00146*(G26+4000)) -> 189010.29 | I15: =(H26+4000)-(0.00146*(H26+4000)) -> 233272.2 | J15: =(I26+4000)-(0.00125*(I26+4000)) -> 277207.35 | K15: =(J26+4000)-(0.00125*(J26+4000)) -> 320689.49 | L15: =(K26+4000)-(0.00125*(K26+4000)) -> 363523.86 | M15: =(L26+4000)-(0.00125*(L26+4000)) -> 405720.12 | N15: =(M26+4000)-(0.00125*(M26+4000)) -> 447287.77 | O15: =(N26+4000)-(0.00125*(N26+4000)) -> 488236.17 | P15: =(O26+4000)-(0.00104*(O26+4000)) -> 529545.46 | Q15: =(P26+4000)-(0.00104*(P26+4000)) -> 570651.16 | R15: =(Q26+4000)-(0.00104*(Q26+4000)) -> 611246.78 | S15: =(R26+4000)-(0.00104*(R26+4000)) -> 651338.66 | T15: =(S26+4000)-(0.00104*(S26+4000)) -> 690933.04 | U15: =(T26+4000)-(0.00104*(T26+4000)) -> 730036.1 | V15: =(U26+4000)-(0.00104*(U26+4000)) -> 768653.94 | W15: =(V26+4000)-(0.00104*(V26+4000)) -> 806792.57 | ... AB15: =(AA26+4000)-(0.00104*(AA26+4000)) -> 990503.25 | AC15: =(AB26+4000)-(0.000833*(AB26+4000)) -> 1027774 | AD15: =(AC26+4000)-(0.000833*(AC26+4000)) -> 1065288.2 | AE15: =(AD26+4000)-(0.000833*(AD26+4000)) -> 1102429.2 | AH15: J | AI15: =(AI14+4000)-0 -> 4000 | AJ15: =(AI26+4000)-0 -> 52000 | AK15: =(AJ26+4000)-0 -> 100000 | AL15: =(AK26+4000)-0 -> 148000 | AM15: =(AL26+4000)-0 -> 196000 | AN15: =(AM26+4000)-0 -> 244000 | AO15: =(AN26+4000)-0 -> 292000 | AP15: =(AO26+4000)-0 -> 340000 | AQ15: =(AP26+4000)-0 -> 388000 | ... BJ15: =(BI26+4000)-0 -> 1300000
A16: =0.0175/12 -> 0.0014583333 | B16: 1.75 | C16: F | D16: =(D15+4000)-(0.00146*(D15+4000)) -> 7982.4885 | E16: =(E15+4000)-(0.00146*(E15+4000)) -> 55390.663 | F16: =(F15+4000)-(0.00146*(F15+4000)) -> 101974.88 | G16: =(G15+4000)-(0.00146*(G15+4000)) -> 147749.47 | H16: =(H15+4000)-(0.00146*(H15+4000)) -> 192728.49 | I16: =(I15+4000)-(0.00146*(I15+4000)) -> 236925.78 | J16: =(J15+4000)-(0.00125*(J15+4000)) -> 280855.84 | K16: =(K15+4000)-(0.00125*(K15+4000)) -> 324283.63 | L16: =(L15+4000)-(0.00125*(L15+4000)) -> 367064.46 | M16: =(M15+4000)-(0.00125*(M15+4000)) -> 409207.97 | N16: =(N15+4000)-(0.00125*(N15+4000)) -> 450723.66 | O16: =(O15+4000)-(0.00125*(O15+4000)) -> 491620.87 | P16: =(P15+4000)-(0.00104*(P15+4000)) -> 532990.57 | Q16: =(Q15+4000)-(0.00104*(Q15+4000)) -> 574053.52 | R16: =(R15+4000)-(0.00104*(R15+4000)) -> 614606.92 | S16: =(S15+4000)-(0.00104*(S15+4000)) -> 654657.1 | T16: =(T15+4000)-(0.00104*(T15+4000)) -> 694210.31 | U16: =(U15+4000)-(0.00104*(U15+4000)) -> 733272.7 | V16: =(V15+4000)-(0.00104*(V15+4000)) -> 771850.38 | W16: =(W15+4000)-(0.00104*(W15+4000)) -> 809949.35 | ... AB16: =(AB15+4000)-(0.00104*(AB15+4000)) -> 993468.97 | AC16: =(AC15+4000)-(0.000833*(AC15+4000)) -> 1030914.6 | AD16: =(AD15+4000)-(0.000833*(AD15+4000)) -> 1068397.5 | AE16: =(AE15+4000)-(0.000833*(AE15+4000)) -> 1105507.5 | AH16: F | AI16: =(AI15+4000)-0 -> 8000 | AJ16: =(AJ15+4000)-0 -> 56000 | AK16: =(AK15+4000)-0 -> 104000 | AL16: =(AL15+4000)-0 -> 152000 | AM16: =(AM15+4000)-0 -> 200000 | AN16: =(AN15+4000)-0 -> 248000 | AO16: =(AO15+4000)-0 -> 296000 | AP16: =(AP15+4000)-0 -> 344000 | ... BJ16: =(BJ15+4000)-0 -> 1304000
A17: =0.015/12 -> 0.00125 | B17: 1.5 | C17: M | D17: =(D16+4000)-(0.00146*(D16+4000)) -> 11964.994 | E17: =(E16+4000)-(0.00146*(E16+4000)) -> 59303.952 | F17: =(F16+4000)-(0.00146*(F16+4000)) -> 105820.16 | G17: =(G16+4000)-(0.00146*(G16+4000)) -> 151527.92 | H17: =(H16+4000)-(0.00146*(H16+4000)) -> 196441.27 | I17: =(I16+4000)-(0.00146*(I16+4000)) -> 240574.03 | J17: =(J16+4000)-(0.00125*(J16+4000)) -> 284499.77 | K17: =(K16+4000)-(0.00125*(K16+4000)) -> 327873.27 | L17: =(L16+4000)-(0.00125*(L16+4000)) -> 370600.63 | M17: =(M16+4000)-(0.00125*(M16+4000)) -> 412691.46 | N17: =(N16+4000)-(0.00125*(N16+4000)) -> 454155.25 | O17: =(O16+4000)-(0.00125*(O16+4000)) -> 495001.35 | P17: =(P16+4000)-(0.00104*(P16+4000)) -> 536432.1 | Q17: =(Q16+4000)-(0.00104*(Q16+4000)) -> 577452.34 | R17: =(R16+4000)-(0.00104*(R16+4000)) -> 617963.57 | S17: =(S16+4000)-(0.00104*(S16+4000)) -> 657972.1 | T17: =(T16+4000)-(0.00104*(T16+4000)) -> 697484.17 | U17: =(U16+4000)-(0.00104*(U16+4000)) -> 736505.94 | V17: =(V16+4000)-(0.00104*(V16+4000)) -> 775043.49 | W17: =(W16+4000)-(0.00104*(W16+4000)) -> 813102.84 | ... AB17: =(AB16+4000)-(0.00104*(AB16+4000)) -> 996431.6 | AC17: =(AC16+4000)-(0.000833*(AC16+4000)) -> 1034052.5 | AD17: =(AD16+4000)-(0.000833*(AD16+4000)) -> 1071504.2 | AE17: =(AE16+4000)-(0.000833*(AE16+4000)) -> 1108583.3 | AH17: M | AI17: =(AI16+4000)-0 -> 12000 | AJ17: =(AJ16+4000)-0 -> 60000 | AK17: =(AK16+4000)-0 -> 108000 | AL17: =(AL16+4000)-0 -> 156000 | AM17: =(AM16+4000)-0 -> 204000 | AN17: =(AN16+4000)-0 -> 252000 | AO17: =(AO16+4000)-0 -> 300000 | AP17: =(AP16+4000)-0 -> 348000 | ... BJ17: =(BJ16+4000)-0 -> 1308000
A18: =0.0125/12 -> 0.0010416667 | B18: 1.25 | C18: A | D18: =(D17+4000)-(0.00146*(D17+4000)) -> 15941.685 | E18: =(E17+4000)-(0.00146*(E17+4000)) -> 63211.528 | F18: =(F17+4000)-(0.00146*(F17+4000)) -> 109659.82 | G18: =(G17+4000)-(0.00146*(G17+4000)) -> 155300.84 | H18: =(H17+4000)-(0.00146*(H17+4000)) -> 200148.63 | I18: =(I17+4000)-(0.00146*(I17+4000)) -> 244216.95 | J18: =(J17+4000)-(0.00125*(J17+4000)) -> 288139.15 | K18: =(K17+4000)-(0.00125*(K17+4000)) -> 331458.43 | L18: =(L17+4000)-(0.00125*(L17+4000)) -> 374132.38 | M18: =(M17+4000)-(0.00125*(M17+4000)) -> 416170.6 | N18: =(N17+4000)-(0.00125*(N17+4000)) -> 457582.56 | O18: =(O17+4000)-(0.00125*(O17+4000)) -> 498377.59 | P18: =(P17+4000)-(0.00104*(P17+4000)) -> 539870.05 | Q18: =(Q17+4000)-(0.00104*(Q17+4000)) -> 580847.63 | R18: =(R17+4000)-(0.00104*(R17+4000)) -> 621316.73 | S18: =(S17+4000)-(0.00104*(S17+4000)) -> 661283.65 | T18: =(T17+4000)-(0.00104*(T17+4000)) -> 700754.63 | U18: =(U17+4000)-(0.00104*(U17+4000)) -> 739735.81 | V18: =(V17+4000)-(0.00104*(V17+4000)) -> 778233.29 | W18: =(W17+4000)-(0.00104*(W17+4000)) -> 816253.05 | ... AB18: =(AB17+4000)-(0.00104*(AB17+4000)) -> 999391.15 | AC18: =(AC17+4000)-(0.000833*(AC17+4000)) -> 1037187.8 | AD18: =(AD17+4000)-(0.000833*(AD17+4000)) -> 1074608.3 | AE18: =(AE17+4000)-(0.000833*(AE17+4000)) -> 1111656.5 | AH18: A | AI18: =(AI17+4000)-0 -> 16000 | AJ18: =(AJ17+4000)-0 -> 64000 | AK18: =(AK17+4000)-0 -> 112000 | AL18: =(AL17+4000)-0 -> 160000 | AM18: =(AM17+4000)-0 -> 208000 | AN18: =(AN17+4000)-0 -> 256000 | AO18: =(AO17+4000)-0 -> 304000 | AP18: =(AP17+4000)-0 -> 352000 | ... BJ18: =(BJ17+4000)-0 -> 1312000
A19: =0.01/12 -> 0.00083333333 | B19: 1 | C19: M | D19: =(D18+4000)-(0.00146*(D18+4000)) -> 19912.57 | E19: =(E18+4000)-(0.00146*(E18+4000)) -> 67113.4 | F19: =(F18+4000)-(0.00146*(F18+4000)) -> 113493.88 | G19: =(G18+4000)-(0.00146*(G18+4000)) -> 159068.27 | H19: =(H18+4000)-(0.00146*(H18+4000)) -> 203850.57 | I19: =(I18+4000)-(0.00146*(I18+4000)) -> 247854.56 | J19: =(J18+4000)-(0.00125*(J18+4000)) -> 291773.97 | K19: =(K18+4000)-(0.00125*(K18+4000)) -> 335039.11 | L19: =(L18+4000)-(0.00125*(L18+4000)) -> 377659.71 | M19: =(M18+4000)-(0.00125*(M18+4000)) -> 419645.38 | N19: =(N18+4000)-(0.00125*(N18+4000)) -> 461005.58 | O19: =(O18+4000)-(0.00104*(O18+4000)) -> 501855.12 | P19: =(P18+4000)-(0.00104*(P18+4000)) -> 543304.43 | Q19: =(Q18+4000)-(0.00104*(Q18+4000)) -> 584239.39 | R19: =(R18+4000)-(0.00104*(R18+4000)) -> 624666.4 | S19: =(S18+4000)-(0.00104*(S18+4000)) -> 664591.75 | T19: =(T18+4000)-(0.00104*(T18+4000)) -> 704021.68 | U19: =(U18+4000)-(0.00104*(U18+4000)) -> 742962.33 | V19: =(V18+4000)-(0.00104*(V18+4000)) -> 781419.77 | ... AA19: =(AA18+4000)-(0.00104*(AA18+4000)) -> 966666.1 | AB19: =(AB18+4000)-(0.000833*(AB18+4000)) -> 1002555.3 | AC19: =(AC18+4000)-(0.000833*(AC18+4000)) -> 1040320.5 | AD19: =(AD18+4000)-(0.000833*(AD18+4000)) -> 1077709.8 | AE19: =(AE18+4000)-(0.000833*(AE18+4000)) -> 1114727.2 | AH19: M | AI19: =(AI18+4000)-0 -> 20000 | AJ19: =(AJ18+4000)-0 -> 68000 | AK19: =(AK18+4000)-0 -> 116000 | AL19: =(AL18+4000)-0 -> 164000 | AM19: =(AM18+4000)-0 -> 212000 | AN19: =(AN18+4000)-0 -> 260000 | AO19: =(AO18+4000)-0 -> 308000 | AP19: =(AP18+4000)-0 -> 356000 | ... BJ19: =(BJ18+4000)-0 -> 1316000
C20: J | D20: =(D19+4000)-(0.00146*(D19+4000)) -> 23877.658 | E20: =(E19+4000)-(0.00146*(E19+4000)) -> 71009.574 | F20: =(F19+4000)-(0.00146*(F19+4000)) -> 117322.34 | G20: =(G19+4000)-(0.00146*(G19+4000)) -> 162830.19 | H20: =(H19+4000)-(0.00146*(H19+4000)) -> 207547.11 | I20: =(I19+4000)-(0.00125*(I19+4000)) -> 251539.74 | J20: =(J19+4000)-(0.00125*(J19+4000)) -> 295404.26 | K20: =(K19+4000)-(0.00125*(K19+4000)) -> 338615.31 | L20: =(L19+4000)-(0.00125*(L19+4000)) -> 381182.64 | M20: =(M19+4000)-(0.00125*(M19+4000)) -> 423115.83 | N20: =(N19+4000)-(0.00125*(N19+4000)) -> 464424.32 | O20: =(O19+4000)-(0.00104*(O19+4000)) -> 505329.03 | P20: =(P19+4000)-(0.00104*(P19+4000)) -> 546735.23 | Q20: =(Q19+4000)-(0.00104*(Q19+4000)) -> 587627.62 | R20: =(R19+4000)-(0.00104*(R19+4000)) -> 628012.59 | S20: =(S19+4000)-(0.00104*(S19+4000)) -> 667896.42 | T20: =(T19+4000)-(0.00104*(T19+4000)) -> 707285.34 | U20: =(U19+4000)-(0.00104*(U19+4000)) -> 746185.49 | V20: =(V19+4000)-(0.00104*(V19+4000)) -> 784602.93 | ... AA20: =(AA19+4000)-(0.00104*(AA19+4000)) -> 969656.6 | AB20: =(AB19+4000)-(0.000833*(AB19+4000)) -> 1005716.9 | AC20: =(AC19+4000)-(0.000833*(AC19+4000)) -> 1043450.5 | AD20: =(AD19+4000)-(0.000833*(AD19+4000)) -> 1080808.8 | AE20: =(AE19+4000)-(0.000833*(AE19+4000)) -> 1117795.3 | AH20: J | AI20: =(AI19+4000)-0 -> 24000 | AJ20: =(AJ19+4000)-0 -> 72000 | AK20: =(AK19+4000)-0 -> 120000 | AL20: =(AL19+4000)-0 -> 168000 | AM20: =(AM19+4000)-0 -> 216000 | AN20: =(AN19+4000)-0 -> 264000 | AO20: =(AO19+4000)-0 -> 312000 | AP20: =(AP19+4000)-0 -> 360000 | ... BJ20: =(BJ19+4000)-0 -> 1320000
C21: J | D21: =(D20+4000)-(0.00146*(D20+4000)) -> 27836.957 | E21: =(E20+4000)-(0.00146*(E20+4000)) -> 74900.06 | F21: =(F20+4000)-(0.00146*(F20+4000)) -> 121145.21 | G21: =(G20+4000)-(0.00146*(G20+4000)) -> 166586.61 | H21: =(H20+4000)-(0.00146*(H20+4000)) -> 211238.25 | I21: =(I20+4000)-(0.00125*(I20+4000)) -> 255220.31 | J21: =(J20+4000)-(0.00125*(J20+4000)) -> 299030 | K21: =(K20+4000)-(0.00125*(K20+4000)) -> 342187.04 | L21: =(L20+4000)-(0.00125*(L20+4000)) -> 384701.16 | M21: =(M20+4000)-(0.00125*(M20+4000)) -> 426581.93 | N21: =(N20+4000)-(0.00125*(N20+4000)) -> 467838.79 | O21: =(O20+4000)-(0.00104*(O20+4000)) -> 508799.33 | P21: =(P20+4000)-(0.00104*(P20+4000)) -> 550162.46 | Q21: =(Q20+4000)-(0.00104*(Q20+4000)) -> 591012.33 | R21: =(R20+4000)-(0.00104*(R20+4000)) -> 631355.29 | S21: =(S20+4000)-(0.00104*(S20+4000)) -> 671197.65 | T21: =(T20+4000)-(0.00104*(T20+4000)) -> 710545.6 | U21: =(U20+4000)-(0.00104*(U20+4000)) -> 749405.29 | V21: =(V20+4000)-(0.00104*(V20+4000)) -> 787782.78 | ... AA21: =(AA20+4000)-(0.00104*(AA20+4000)) -> 972644 | AB21: =(AB20+4000)-(0.000833*(AB20+4000)) -> 1008875.8 | AC21: =(AC20+4000)-(0.000833*(AC20+4000)) -> 1046578 | AD21: =(AD20+4000)-(0.000833*(AD20+4000)) -> 1083905.1 | AE21: =(AE20+4000)-(0.000833*(AE20+4000)) -> 1120860.8 | AH21: J | AI21: =(AI20+4000)-0 -> 28000 | AJ21: =(AJ20+4000)-0 -> 76000 | AK21: =(AK20+4000)-0 -> 124000 | AL21: =(AL20+4000)-0 -> 172000 | AM21: =(AM20+4000)-0 -> 220000 | AN21: =(AN20+4000)-0 -> 268000 | AO21: =(AO20+4000)-0 -> 316000 | AP21: =(AP20+4000)-0 -> 364000 | ... BJ21: =(BJ20+4000)-0 -> 1324000
C22: A | D22: =(D21+4000)-(0.00146*(D21+4000)) -> 31790.475 | E22: =(E21+4000)-(0.00146*(E21+4000)) -> 78784.866 | F22: =(F21+4000)-(0.00146*(F21+4000)) -> 124962.49 | G22: =(G21+4000)-(0.00146*(G21+4000)) -> 170337.56 | H22: =(H21+4000)-(0.00146*(H21+4000)) -> 214924 | I22: =(I21+4000)-(0.00125*(I21+4000)) -> 258896.29 | J22: =(J21+4000)-(0.00125*(J21+4000)) -> 302651.21 | K22: =(K21+4000)-(0.00125*(K21+4000)) -> 345754.31 | L22: =(L21+4000)-(0.00125*(L21+4000)) -> 388215.28 | M22: =(M21+4000)-(0.00125*(M21+4000)) -> 430043.7 | N22: =(N21+4000)-(0.00125*(N21+4000)) -> 471248.99 | O22: =(O21+4000)-(0.00104*(O21+4000)) -> 512266.02 | P22: =(P21+4000)-(0.00104*(P21+4000)) -> 553586.14 | Q22: =(Q21+4000)-(0.00104*(Q21+4000)) -> 594393.52 | R22: =(R21+4000)-(0.00104*(R21+4000)) -> 634694.52 | S22: =(S21+4000)-(0.00104*(S21+4000)) -> 674495.44 | T22: =(T21+4000)-(0.00104*(T21+4000)) -> 713802.47 | U22: =(U21+4000)-(0.00104*(U21+4000)) -> 752621.75 | V22: =(V21+4000)-(0.00104*(V21+4000)) -> 790959.33 | ... AA22: =(AA21+4000)-(0.00104*(AA21+4000)) -> 975628.29 | AB22: =(AB21+4000)-(0.000833*(AB21+4000)) -> 1012032 | AC22: =(AC21+4000)-(0.000833*(AC21+4000)) -> 1049702.9 | AD22: =(AD21+4000)-(0.000833*(AD21+4000)) -> 1086998.9 | AE22: =(AE21+4000)-(0.000833*(AE21+4000)) -> 1123923.8 | AH22: A | AI22: =(AI21+4000)-0 -> 32000 | AJ22: =(AJ21+4000)-0 -> 80000 | AK22: =(AK21+4000)-0 -> 128000 | AL22: =(AL21+4000)-0 -> 176000 | AM22: =(AM21+4000)-0 -> 224000 | AN22: =(AN21+4000)-0 -> 272000 | AO22: =(AO21+4000)-0 -> 320000 | AP22: =(AP21+4000)-0 -> 368000 | ... BJ22: =(BJ21+4000)-0 -> 1328000
C23: S | D23: =(D22+4000)-(0.00146*(D22+4000)) -> 35738.221 | E23: =(E22+4000)-(0.00146*(E22+4000)) -> 82664 | F23: =(F22+4000)-(0.00146*(F22+4000)) -> 128774.21 | G23: =(G22+4000)-(0.00146*(G22+4000)) -> 174083.02 | H23: =(H22+4000)-(0.00146*(H22+4000)) -> 218604.37 | I23: =(I22+4000)-(0.00125*(I22+4000)) -> 262567.67 | J23: =(J22+4000)-(0.00125*(J22+4000)) -> 306267.9 | K23: =(K22+4000)-(0.00125*(K22+4000)) -> 349317.12 | L23: =(L22+4000)-(0.00125*(L22+4000)) -> 391725.01 | M23: =(M22+4000)-(0.00125*(M22+4000)) -> 433501.15 | N23: =(N22+4000)-(0.00125*(N22+4000)) -> 474654.93 | O23: =(O22+4000)-(0.00104*(O22+4000)) -> 515729.1 | P23: =(P22+4000)-(0.00104*(P22+4000)) -> 557006.25 | Q23: =(Q22+4000)-(0.00104*(Q22+4000)) -> 597771.19 | R23: =(R22+4000)-(0.00104*(R22+4000)) -> 638030.28 | S23: =(S22+4000)-(0.00104*(S22+4000)) -> 677789.81 | T23: =(T22+4000)-(0.00104*(T22+4000)) -> 717055.96 | U23: =(U22+4000)-(0.00104*(U22+4000)) -> 755834.87 | V23: =(V22+4000)-(0.00104*(V22+4000)) -> 794132.57 | ... AA23: =(AA22+4000)-(0.00104*(AA22+4000)) -> 978609.48 | AB23: =(AB22+4000)-(0.000833*(AB22+4000)) -> 1015185.7 | AC23: =(AC22+4000)-(0.000833*(AC22+4000)) -> 1052825.2 | AD23: =(AD22+4000)-(0.000833*(AD22+4000)) -> 1090090.1 | AE23: =(AE22+4000)-(0.000833*(AE22+4000)) -> 1126984.2 | AH23: S | AI23: =(AI22+4000)-0 -> 36000 | AJ23: =(AJ22+4000)-0 -> 84000 | AK23: =(AK22+4000)-0 -> 132000 | AL23: =(AL22+4000)-0 -> 180000 | AM23: =(AM22+4000)-0 -> 228000 | AN23: =(AN22+4000)-0 -> 276000 | AO23: =(AO22+4000)-0 -> 324000 | AP23: =(AP22+4000)-0 -> 372000 | ... BJ23: =(BJ22+4000)-0 -> 1332000
C24: O | D24: =(D23+4000)-(0.00146*(D23+4000)) -> 39680.203 | E24: =(E23+4000)-(0.00146*(E23+4000)) -> 86537.471 | F24: =(F23+4000)-(0.00146*(F23+4000)) -> 132580.36 | G24: =(G23+4000)-(0.00146*(G23+4000)) -> 177823.02 | H24: =(H23+4000)-(0.00146*(H23+4000)) -> 222279.37 | I24: =(I23+4000)-(0.00125*(I23+4000)) -> 266234.46 | J24: =(J23+4000)-(0.00125*(J23+4000)) -> 309880.06 | K24: =(K23+4000)-(0.00125*(K23+4000)) -> 352875.47 | L24: =(L23+4000)-(0.00125*(L23+4000)) -> 395230.36 | M24: =(M23+4000)-(0.00125*(M23+4000)) -> 436954.27 | N24: =(N23+4000)-(0.00125*(N23+4000)) -> 478056.61 | O24: =(O23+4000)-(0.00104*(O23+4000)) -> 519188.58 | P24: =(P23+4000)-(0.00104*(P23+4000)) -> 560422.8 | Q24: =(Q23+4000)-(0.00104*(Q23+4000)) -> 601145.34 | R24: =(R23+4000)-(0.00104*(R23+4000)) -> 641362.57 | S24: =(S23+4000)-(0.00104*(S23+4000)) -> 681080.74 | T24: =(T23+4000)-(0.00104*(T23+4000)) -> 720306.06 | U24: =(U23+4000)-(0.00104*(U23+4000)) -> 759044.64 | V24: =(V23+4000)-(0.00104*(V23+4000)) -> 797302.51 | ... AA24: =(AA23+4000)-(0.00104*(AA23+4000)) -> 981587.56 | AB24: =(AB23+4000)-(0.000833*(AB23+4000)) -> 1018336.7 | AC24: =(AC23+4000)-(0.000833*(AC23+4000)) -> 1055944.8 | AD24: =(AD23+4000)-(0.000833*(AD23+4000)) -> 1093178.7 | AE24: =(AE23+4000)-(0.000833*(AE23+4000)) -> 1130042.1 | AH24: O | AI24: =(AI23+4000)-0 -> 40000 | AJ24: =(AJ23+4000)-0 -> 88000 | AK24: =(AK23+4000)-0 -> 136000 | AL24: =(AL23+4000)-0 -> 184000 | AM24: =(AM23+4000)-0 -> 232000 | AN24: =(AN23+4000)-0 -> 280000 | AO24: =(AO23+4000)-0 -> 328000 | AP24: =(AP23+4000)-0 -> 376000 | ... BJ24: =(BJ23+4000)-0 -> 1336000
C25: N | D25: =(D24+4000)-(0.00146*(D24+4000)) -> 43616.43 | E25: =(E24+4000)-(0.00146*(E24+4000)) -> 90405.286 | F25: =(F24+4000)-(0.00146*(F24+4000)) -> 136380.95 | G25: =(G24+4000)-(0.00146*(G24+4000)) -> 181557.56 | H25: =(H24+4000)-(0.00146*(H24+4000)) -> 225949 | I25: =(I24+4000)-(0.00125*(I24+4000)) -> 269896.66 | J25: =(J24+4000)-(0.00125*(J24+4000)) -> 313487.71 | K25: =(K24+4000)-(0.00125*(K24+4000)) -> 356429.37 | L25: =(L24+4000)-(0.00125*(L24+4000)) -> 398731.32 | M25: =(M24+4000)-(0.00125*(M24+4000)) -> 440403.08 | N25: =(N24+4000)-(0.00125*(N24+4000)) -> 481454.04 | O25: =(O24+4000)-(0.00104*(O24+4000)) -> 522644.47 | P25: =(P24+4000)-(0.00104*(P24+4000)) -> 563835.8 | Q25: =(Q24+4000)-(0.00104*(Q24+4000)) -> 604515.99 | R25: =(R24+4000)-(0.00104*(R24+4000)) -> 644691.39 | S25: =(S24+4000)-(0.00104*(S24+4000)) -> 684368.26 | T25: =(T24+4000)-(0.00104*(T24+4000)) -> 723552.78 | U25: =(U24+4000)-(0.00104*(U24+4000)) -> 762251.07 | V25: =(V24+4000)-(0.00104*(V24+4000)) -> 800469.16 | ... AA25: =(AA24+4000)-(0.00104*(AA24+4000)) -> 984562.55 | AB25: =(AB24+4000)-(0.000833*(AB24+4000)) -> 1021485.1 | AC25: =(AC24+4000)-(0.000833*(AC24+4000)) -> 1059061.9 | AD25: =(AD24+4000)-(0.000833*(AD24+4000)) -> 1096264.8 | AE25: =(AE24+4000)-(0.000833*(AE24+4000)) -> 1133097.5 | AH25: N | AI25: =(AI24+4000)-0 -> 44000 | AJ25: =(AJ24+4000)-0 -> 92000 | AK25: =(AK24+4000)-0 -> 140000 | AL25: =(AL24+4000)-0 -> 188000 | AM25: =(AM24+4000)-0 -> 236000 | AN25: =(AN24+4000)-0 -> 284000 | AO25: =(AO24+4000)-0 -> 332000 | AP25: =(AP24+4000)-0 -> 380000 | ... BJ25: =(BJ24+4000)-0 -> 1340000
C26: D | D26: =(D25+4000)-(0.00146*(D25+4000)) -> 47546.91 | E26: =(E25+4000)-(0.00146*(E25+4000)) -> 94267.454 | F26: =(F25+4000)-(0.00146*(F25+4000)) -> 140176 | G26: =(G25+4000)-(0.00146*(G25+4000)) -> 185286.65 | H26: =(H25+4000)-(0.00146*(H25+4000)) -> 229613.28 | I26: =(I25+4000)-(0.00125*(I25+4000)) -> 273554.29 | J26: =(J25+4000)-(0.00125*(J25+4000)) -> 317090.85 | K26: =(K25+4000)-(0.00125*(K25+4000)) -> 359978.84 | L26: =(L25+4000)-(0.00125*(L25+4000)) -> 402227.91 | M26: =(M25+4000)-(0.00125*(M25+4000)) -> 443847.58 | N26: =(N25+4000)-(0.00125*(N25+4000)) -> 484847.23 | O26: =(O25+4000)-(0.00104*(O25+4000)) -> 526096.76 | P26: =(P25+4000)-(0.00104*(P25+4000)) -> 567245.25 | Q26: =(Q25+4000)-(0.00104*(Q25+4000)) -> 607883.14 | R26: =(R25+4000)-(0.00104*(R25+4000)) -> 648016.75 | S26: =(S25+4000)-(0.00104*(S25+4000)) -> 687652.36 | T26: =(T25+4000)-(0.00104*(T25+4000)) -> 726796.13 | U26: =(U25+4000)-(0.00104*(U25+4000)) -> 765454.17 | V26: =(V25+4000)-(0.00104*(V25+4000)) -> 803632.51 | ... AA26: =(AA25+4000)-(0.00104*(AA25+4000)) -> 987534.45 | AB26: =(AB25+4000)-(0.000833*(AB25+4000)) -> 1024630.9 | AC26: =(AC25+4000)-(0.000833*(AC25+4000)) -> 1062176.4 | AD26: =(AD25+4000)-(0.000833*(AD25+4000)) -> 1099348.2 | AE26: =(AE25+4000)-(0.000833*(AE25+4000)) -> 1136150.3 | AH26: D | AI26: =(AI25+4000)-0 -> 48000 | AJ26: =(AJ25+4000)-0 -> 96000 | AK26: =(AK25+4000)-0 -> 144000 | AL26: =(AL25+4000)-0 -> 192000 | AM26: =(AM25+4000)-0 -> 240000 | AN26: =(AN25+4000)-0 -> 288000 | AO26: =(AO25+4000)-0 -> 336000 | AP26: =(AP25+4000)-0 -> 384000 | ... BJ26: =(BJ25+4000)-0 -> 1344000
AB28: After saving $4K/mo x 25 years you should have (4000x12x25) = 1,200,000 | BG28: After saving $4K/mo x 25 years you should have (4000x12x25) = 1,200,000
AB29: 1.2M - 1,024,631 = $175,369. | BG29: 1.2M - 1,024,631 = $175,369.
AB30: Average = 7,014.76/yr x 25yrs | BG30: Average = 7,014.76/yr x 25yrs
AB31: Let's see what happens if you actually invest your money, get a return, and have an opportunity cost of your advisor's fee being compounded annually | BG31: Let's see what happens if you actually invest your money, get a return, and have an opportunity cost of your advisor's fee being compounded annually
D32: Scenario 2 | AI32: Scenario 2 | AJ32: WITHOUT AN ADVISOR
D33: Assume 4% annual return on investments | AI33: Assume 4% annual return on investments
D34: Assume 4K/mo invested | AI34: Assume 4K/mo invested
D35: Y1 | E35: Y2 | F35: Y3 | G35: Y4 | H35: Y5 | I35: Y6 | J35: Y7 | K35: Y8 | L35: Y9 | M35: Y10 | N35: Y11 | O35: Y12 | P35: Y13 | Q35: Y14 | R35: Y15 | S35: Y16 | T35: Y17 | U35: Y18 | V35: Y19 | W35: Y20 | X35: Y21 | Y35: Y22 | Z35: Y23 | AA35: Y24 | AB35: Y25 | AC35: Y26 | AD35: Y27 | AE35: Y28 | AI35: Y1 | AJ35: Y2 | AK35: Y3 | AL35: Y4 | AM35: Y5 | AN35: Y6 | AO35: Y7 | AP35: Y8 | AQ35: Y9 | AR35: Y10 | AS35: Y11 | AT35: Y12 | AU35: Y13 | AV35: Y14 | AW35: Y15 | AX35: Y16 | AY35: Y17 | AZ35: Y18 | BA35: Y19 | BB35: Y20 | BC35: Y21 | BD35: Y22 | BE35: Y23 | BF35: Y24 | BG35: Y25 | BH35: Y26 | BI35: Y27 | BJ35: Y28
D36: 0 | AI36: 0
D37: =(D36+4000)*1.00328-(0.00146*(D36+4000)) -> 4007.28 | E37: =(D48+4000)*1.00328-(0.00146*(D48+4000)) -> 52667.327 | F37: =(E48+4000)*1.00328-(0.00146*(E48+4000)) -> 102400.81 | G37: =(F48+4000)*1.00328-(0.00146*(F48+4000)) -> 153231.42 | H37: =(G48+4000)*1.00328-(0.00146*(G48+4000)) -> 205183.34 | I37: =(H48+4000)*1.00328-(0.00125*(H48+4000)) -> 258388.77 | J37: =(I48+4000)*1.00328-(0.00125*(I48+4000)) -> 313391.98 | K37: =(J48+4000)*1.00328-(0.00125*(J48+4000)) -> 369750.12 | L37: =(K48+4000)*1.00328-(0.00125*(K48+4000)) -> 427496.58 | M37: =(L48+4000)*1.00328-(0.00125*(L48+4000)) -> 486665.55 | N37: =(M48+4000)*1.00328-(0.00104*(M48+4000)) -> 548402.1 | O37: =(N48+4000)*1.00328-(0.00104*(N48+4000)) -> 612030.77 | P37: =(O48+4000)*1.00328-(0.00104*(O48+4000)) -> 677391.01 | Q37: =(P48+4000)*1.00328-(0.00104*(P48+4000)) -> 744529.95 | R37: =(Q48+4000)*1.00328-(0.00104*(Q48+4000)) -> 813495.97 | S37: =(R48+4000)*1.00328-(0.00104*(R48+4000)) -> 884338.82 | T37: =(S48+4000)*1.00328-(0.00104*(S48+4000)) -> 957109.55 | U37: =(T48+4000)*1.00328-(0.00125*(T48+4000)) -> 1032697.8 | V37: =(U48+4000)*1.00328-(0.00125*(U48+4000)) -> 1106775.2 | W37: =(V48+4000)*1.00328-(0.00125*(V48+4000)) -> 1182677.4 | X37: =(W48+4000)*1.00328-(0.00125*(W48+4000)) -> 1260449.4 | Y37: =(X48+4000)*1.00328-(0.00125*(X48+4000)) -> 1340137.2 | Z37: =(Y48+4000)*1.00328-(0.00125*(Y48+4000)) -> 1421788 | AA37: =(Z48+4000)*1.00328-(0.00125*(Z48+4000)) -> 1505450.1 | AB37: =(AA48+4000)*1.00328-(0.00125*(AA48+4000)) -> 1591173.2 | ... AE37: =(AD48+4000)*1.00328-(0.00125*(AD48+4000)) -> 1861222 | AI37: =(AI36+4000)*1.00328-0 -> 4013.12 | AJ37: =(AI48+4000)*1.00328-0 -> 53209.726 | AK37: =(AJ48+4000)*1.00328-0 -> 104378.03 | AL37: =(AK48+4000)*1.00328-0 -> 157597.05 | AM37: =(AL48+4000)*1.00328-0 -> 212948.97 | AN37: =(AM48+4000)*1.00328-0 -> 270519.28 | AO37: =(AN48+4000)*1.00328-0 -> 330396.89 | AP37: =(AO48+4000)*1.00328-0 -> 392674.26 | AQ37: =(AP48+4000)*1.00328-0 -> 457447.58 | ... BJ37: =(BI48+4000)*1.00328-0 -> 2323058.5
D38: =(D37+4000)*1.00328-(0.00146*(D37+4000)) -> 8021.8532 | E38: =(E37+4000)*1.00328-(0.00146*(E37+4000)) -> 56770.462 | F38: =(F37+4000)*1.00328-(0.00146*(F37+4000)) -> 106594.46 | G38: =(G37+4000)*1.00328-(0.00146*(G37+4000)) -> 157517.58 | H38: =(H37+4000)*1.00328-(0.00146*(H37+4000)) -> 209564.05 | I38: =(I37+4000)*1.00328-(0.00125*(I37+4000)) -> 262921.42 | J38: =(J37+4000)*1.00328-(0.00125*(J37+4000)) -> 318036.28 | K38: =(K37+4000)*1.00328-(0.00125*(K37+4000)) -> 374508.83 | L38: =(L37+4000)*1.00328-(0.00125*(L37+4000)) -> 432372.52 | M38: =(M37+4000)*1.00328-(0.00125*(M37+4000)) -> 491661.6 | N38: =(N37+4000)*1.00328-(0.00104*(N37+4000)) -> 553639.48 | O38: =(O37+4000)*1.00328-(0.00104*(O37+4000)) -> 617410.68 | P38: =(P37+4000)*1.00328-(0.00104*(P37+4000)) -> 682917.33 | Q38: =(Q37+4000)*1.00328-(0.00104*(Q37+4000)) -> 750206.65 | R38: =(R37+4000)*1.00328-(0.00104*(R37+4000)) -> 819327.16 | S38: =(S37+4000)*1.00328-(0.00104*(S37+4000)) -> 890328.7 | T38: =(T37+4000)*1.00328-(0.00104*(T37+4000)) -> 963262.44 | U38: =(U37+4000)*1.00328-(0.00125*(U37+4000)) -> 1038802.3 | V38: =(V37+4000)*1.00328-(0.00125*(V37+4000)) -> 1113030.1 | W38: =(W37+4000)*1.00328-(0.00125*(W37+4000)) -> 1189086.3 | X38: =(X37+4000)*1.00328-(0.00125*(X37+4000)) -> 1267016.2 | Y38: =(Y37+4000)*1.00328-(0.00125*(Y37+4000)) -> 1346865.8 | Z38: =(Z37+4000)*1.00328-(0.00125*(Z37+4000)) -> 1428682.3 | AA38: =(AA37+4000)*1.00328-(0.00125*(AA37+4000)) -> 1512514.3 | AB38: =(AB37+4000)*1.00328-(0.00125*(AB37+4000)) -> 1598411.4 | ... AE38: =(AE37+4000)*1.00328-(0.00125*(AE37+4000)) -> 1869008.4 | AI38: =(AI37+4000)*1.00328-0 -> 8039.403 | AJ38: =(AJ37+4000)*1.00328-0 -> 57397.374 | AK38: =(AK37+4000)*1.00328-0 -> 108733.51 | AL38: =(AL37+4000)*1.00328-0 -> 162127.09 | AM38: =(AM37+4000)*1.00328-0 -> 217660.56 | AN38: =(AN37+4000)*1.00328-0 -> 275419.71 | AO38: =(AO37+4000)*1.00328-0 -> 335493.71 | AP38: =(AP37+4000)*1.00328-0 -> 397975.36 | ... BJ38: =(BJ37+4000)*1.00328-0 -> 2334691.3
A39: =0.0175/12 -> 0.0014583333 | B39: 1.75 | D39: =(D38+4000)*1.00328-(0.00146*(D38+4000)) -> 12043.733 | E39: =(E38+4000)*1.00328-(0.00146*(E38+4000)) -> 60881.064 | F39: =(F38+4000)*1.00328-(0.00146*(F38+4000)) -> 110795.74 | G39: =(G38+4000)*1.00328-(0.00146*(G38+4000)) -> 161811.54 | H39: =(H38+4000)*1.00328-(0.00146*(H38+4000)) -> 213952.74 | I39: =(I38+4000)*1.00328-(0.00125*(I38+4000)) -> 267463.27 | J39: =(J38+4000)*1.00328-(0.00125*(J38+4000)) -> 322690.02 | K39: =(K38+4000)*1.00328-(0.00125*(K38+4000)) -> 379277.2 | L39: =(L38+4000)*1.00328-(0.00125*(L38+4000)) -> 437258.35 | M39: =(M38+4000)*1.00328-(0.00125*(M38+4000)) -> 496667.8 | N39: =(N38+4000)*1.00328-(0.00104*(N38+4000)) -> 558888.59 | O39: =(O38+4000)*1.00328-(0.00104*(O38+4000)) -> 622802.64 | P39: =(P38+4000)*1.00328-(0.00104*(P38+4000)) -> 688456.02 | Q39: =(Q38+4000)*1.00328-(0.00104*(Q38+4000)) -> 755896.08 | R39: =(R38+4000)*1.00328-(0.00104*(R38+4000)) -> 825171.42 | S39: =(S38+4000)*1.00328-(0.00104*(S38+4000)) -> 896331.99 | T39: =(T38+4000)*1.00328-(0.00104*(T38+4000)) -> 969429.11 | U39: =(U38+4000)*1.00328-(0.00125*(U38+4000)) -> 1044919.2 | V39: =(V38+4000)*1.00328-(0.00125*(V38+4000)) -> 1119297.6 | W39: =(W38+4000)*1.00328-(0.00125*(W38+4000)) -> 1195508.3 | X39: =(X38+4000)*1.00328-(0.00125*(X38+4000)) -> 1273596.4 | Y39: =(Y38+4000)*1.00328-(0.00125*(Y38+4000)) -> 1353608 | Z39: =(Z38+4000)*1.00328-(0.00125*(Z38+4000)) -> 1435590.7 | AA39: =(AA38+4000)*1.00328-(0.00125*(AA38+4000)) -> 1519592.8 | AB39: =(AB38+4000)*1.00328-(0.00125*(AB38+4000)) -> 1605664.3 | ... AE39: =(AE38+4000)*1.00328-(0.00125*(AE38+4000)) -> 1876810.6 | AI39: =(AI38+4000)*1.00328-0 -> 12078.892 | AJ39: =(AJ38+4000)*1.00328-0 -> 61598.758 | AK39: =(AK38+4000)*1.00328-0 -> 113103.27 | AL39: =(AL38+4000)*1.00328-0 -> 166671.98 | AM39: =(AM38+4000)*1.00328-0 -> 222387.61 | AN39: =(AN38+4000)*1.00328-0 -> 280336.2 | AO39: =(AO38+4000)*1.00328-0 -> 340607.25 | AP39: =(AP38+4000)*1.00328-0 -> 403293.83 | ... BJ39: =(BJ38+4000)*1.00328-0 -> 2346362.2
A40: =0.015/12 -> 0.00125 | B40: 1.5 | D40: =(D39+4000)*1.00328-(0.00146*(D39+4000)) -> 16072.933 | E40: =(E39+4000)*1.00328-(0.00146*(E39+4000)) -> 64999.147 | F40: =(F39+4000)*1.00328-(0.00146*(F39+4000)) -> 115004.67 | G40: =(G39+4000)*1.00328-(0.00146*(G39+4000)) -> 166113.32 | H40: =(H39+4000)*1.00328-(0.00146*(H39+4000)) -> 218349.41 | I40: =(I39+4000)*1.00328-(0.00125*(I39+4000)) -> 272014.34 | J40: =(J39+4000)*1.00328-(0.00125*(J39+4000)) -> 327353.2 | K40: =(K39+4000)*1.00328-(0.00125*(K39+4000)) -> 384055.26 | L40: =(L39+4000)*1.00328-(0.00125*(L39+4000)) -> 442154.11 | M40: =(M39+4000)*1.00328-(0.00104*(M39+4000)) -> 501789.29 | N40: =(N39+4000)*1.00328-(0.00104*(N39+4000)) -> 564149.46 | O40: =(O39+4000)*1.00328-(0.00104*(O39+4000)) -> 628206.68 | P40: =(P39+4000)*1.00328-(0.00104*(P39+4000)) -> 694007.13 | Q40: =(Q39+4000)*1.00328-(0.00104*(Q39+4000)) -> 761598.24 | R40: =(R39+4000)*1.00328-(0.00104*(R39+4000)) -> 831028.76 | S40: =(S39+4000)*1.00328-(0.00104*(S39+4000)) -> 902348.74 | T40: =(T39+4000)*1.00328-(0.00104*(T39+4000)) -> 975609.59 | U40: =(U39+4000)*1.00328-(0.00125*(U39+4000)) -> 1051048.5 | V40: =(V39+4000)*1.00328-(0.00125*(V39+4000)) -> 1125577.9 | W40: =(W39+4000)*1.00328-(0.00125*(W39+4000)) -> 1201943.3 | X40: =(X39+4000)*1.00328-(0.00125*(X39+4000)) -> 1280189.9 | Y40: =(Y39+4000)*1.00328-(0.00125*(Y39+4000)) -> 1360364 | Z40: =(Z39+4000)*1.00328-(0.00125*(Z39+4000)) -> 1442513 | AA40: =(AA39+4000)*1.00328-(0.00125*(AA39+4000)) -> 1526685.7 | AB40: =(AB39+4000)*1.00328-(0.00125*(AB39+4000)) -> 1612932 | ... AE40: =(AE39+4000)*1.00328-(0.00125*(AE39+4000)) -> 1884628.7 | AI40: =(AI39+4000)*1.00328-0 -> 16131.631 | AJ40: =(AJ39+4000)*1.00328-0 -> 65813.922 | AK40: =(AK39+4000)*1.00328-0 -> 117487.37 | AL40: =(AL39+4000)*1.00328-0 -> 171231.79 | AM40: =(AM39+4000)*1.00328-0 -> 227130.16 | AN40: =(AN39+4000)*1.00328-0 -> 285268.83 | AO40: =(AO39+4000)*1.00328-0 -> 345737.56 | AP40: =(AP39+4000)*1.00328-0 -> 408629.76 | ... BJ40: =(BJ39+4000)*1.00328-0 -> 2358071.4
A41: =0.0125/12 -> 0.0010416667 | B41: 1.25 | D41: =(D40+4000)*1.00328-(0.00146*(D40+4000)) -> 20109.465 | E41: =(E40+4000)*1.00328-(0.00146*(E40+4000)) -> 69124.726 | F41: =(F40+4000)*1.00328-(0.00146*(F40+4000)) -> 119221.26 | G41: =(G40+4000)*1.00328-(0.00146*(G40+4000)) -> 170422.92 | H41: =(H40+4000)*1.00328-(0.00146*(H40+4000)) -> 222754.09 | I41: =(I40+4000)*1.00328-(0.00125*(I40+4000)) -> 276574.65 | J41: =(J40+4000)*1.00328-(0.00125*(J40+4000)) -> 332025.84 | K41: =(K40+4000)*1.00328-(0.00125*(K40+4000)) -> 388843.01 | L41: =(L40+4000)*1.00328-(0.00125*(L40+4000)) -> 447059.8 | M41: =(M40+4000)*1.00328-(0.00104*(M40+4000)) -> 506922.26 | N41: =(N40+4000)*1.00328-(0.00104*(N40+4000)) -> 569422.12 | O41: =(O40+4000)*1.00328-(0.00104*(O40+4000)) -> 633622.82 | P41: =(P40+4000)*1.00328-(0.00104*(P40+4000)) -> 699570.66 | Q41: =(Q40+4000)*1.00328-(0.00104*(Q40+4000)) -> 767313.18 | R41: =(R40+4000)*1.00328-(0.00104*(R40+4000)) -> 836899.23 | S41: =(S40+4000)*1.00328-(0.00104*(S40+4000)) -> 908378.96 | T41: =(T40+4000)*1.00328-(0.00104*(T40+4000)) -> 981803.91 | U41: =(U40+4000)*1.00328-(0.00125*(U40+4000)) -> 1057190.2 | V41: =(V40+4000)*1.00328-(0.00125*(V40+4000)) -> 1131871 | W41: =(W40+4000)*1.00328-(0.00125*(W40+4000)) -> 1208391.4 | X41: =(X40+4000)*1.00328-(0.00125*(X40+4000)) -> 1286796.8 | Y41: =(Y40+4000)*1.00328-(0.00125*(Y40+4000)) -> 1367133.6 | Z41: =(Z40+4000)*1.00328-(0.00125*(Z40+4000)) -> 1449449.4 | AA41: =(AA40+4000)*1.00328-(0.00125*(AA40+4000)) -> 1533793 | AB41: =(AB40+4000)*1.00328-(0.00125*(AB40+4000)) -> 1620214.3 | ... AE41: =(AE40+4000)*1.00328-(0.00125*(AE40+4000)) -> 1892462.6 | AI41: =(AI40+4000)*1.00328-0 -> 20197.663 | AJ41: =(AJ40+4000)*1.00328-0 -> 70042.911 | AK41: =(AK40+4000)*1.00328-0 -> 121885.85 | AL41: =(AL40+4000)*1.00328-0 -> 175806.55 | AM41: =(AM40+4000)*1.00328-0 -> 231888.27 | AN41: =(AN40+4000)*1.00328-0 -> 290217.63 | AO41: =(AO40+4000)*1.00328-0 -> 350884.7 | AP41: =(AP40+4000)*1.00328-0 -> 413983.18 | ... BJ41: =(BJ40+4000)*1.00328-0 -> 2369819
A42: =0.01/12 -> 0.00083333333 | B42: 1 | D42: =(D41+4000)*1.00328-(0.00146*(D41+4000)) -> 24153.345 | E42: =(E41+4000)*1.00328-(0.00146*(E41+4000)) -> 73257.813 | F42: =(F41+4000)*1.00328-(0.00146*(F41+4000)) -> 123445.52 | G42: =(G41+4000)*1.00328-(0.00146*(G41+4000)) -> 174740.37 | H42: =(H41+4000)*1.00328-(0.00146*(H41+4000)) -> 227166.78 | I42: =(I41+4000)*1.00328-(0.00125*(I41+4000)) -> 281144.22 | J42: =(J41+4000)*1.00328-(0.00125*(J41+4000)) -> 336707.98 | K42: =(K41+4000)*1.00328-(0.00125*(K41+4000)) -> 393640.48 | L42: =(L41+4000)*1.00328-(0.00125*(L41+4000)) -> 451975.45 | M42: =(M41+4000)*1.00328-(0.00104*(M41+4000)) -> 512066.73 | N42: =(N41+4000)*1.00328-(0.00104*(N41+4000)) -> 574706.58 | O42: =(O41+4000)*1.00328-(0.00104*(O41+4000)) -> 639051.1 | P42: =(P41+4000)*1.00328-(0.00104*(P41+4000)) -> 705146.66 | Q42: =(Q41+4000)*1.00328-(0.00104*(Q41+4000)) -> 773040.92 | R42: =(R41+4000)*1.00328-(0.00104*(R41+4000)) -> 842782.84 | S42: =(S41+4000)*1.00328-(0.00104*(S41+4000)) -> 914422.69 | T42: =(T41+4000)*1.00328-(0.00104*(T41+4000)) -> 988012.12 | U42: =(U41+4000)*1.00328-(0.00125*(U41+4000)) -> 1063344.4 | V42: =(V41+4000)*1.00328-(0.00125*(V41+4000)) -> 1138176.8 | W42: =(W41+4000)*1.00328-(0.00125*(W41+4000)) -> 1214852.5 | X42: =(X41+4000)*1.00328-(0.00125*(X41+4000)) -> 1293417.1 | Y42: =(Y41+4000)*1.00328-(0.00125*(Y41+4000)) -> 1373917 | Z42: =(Z41+4000)*1.00328-(0.00125*(Z41+4000)) -> 1456399.9 | AA42: =(AA41+4000)*1.00328-(0.00125*(AA41+4000)) -> 1540914.8 | AB42: =(AB41+4000)*1.00328-(0.00125*(AB41+4000)) -> 1627511.5 | ... AE42: =(AE41+4000)*1.00328-(0.00125*(AE41+4000)) -> 1900312.4 | AI42: =(AI41+4000)*1.00328-0 -> 24277.031 | AJ42: =(AJ41+4000)*1.00328-0 -> 74285.772 | AK42: =(AK41+4000)*1.00328-0 -> 126298.76 | AL42: =(AL41+4000)*1.00328-0 -> 180396.31 | AM42: =(AM41+4000)*1.00328-0 -> 236661.98 | AN42: =(AN41+4000)*1.00328-0 -> 295182.66 | AO42: =(AO41+4000)*1.00328-0 -> 356048.72 | AP42: =(AP41+4000)*1.00328-0 -> 419354.17 | ... BJ42: =(BJ41+4000)*1.00328-0 -> 2381605.1
...

Sheet 5K
A1: Cost of a Financial Advisor
A3: 0 - 250,000 | B3: 0.0175
A4: 250,000 - 500,000 | B4: 0.015 | D4: They calculate their fee based on the daily closing value of your account, averaged over each month x the monthly portion of your annual rate.
A5: 500,000 - 1,000,000 | B5: 0.0125 | D5: Ex. 1. If daily average closing value of my account is $12,000 and the monthly fee is 0.146% (1.75%/12) then my fee for the month is (12,000 * 0.00146) = $17.52
A6: 1,000,000 - 2,000,000 | B6: 0.01 | D6: Ex. 2. If the following month I have $16,000 in my account, the fee for that month is 16,000 x 0.00146 = 23.36
A7: 2,000,000 - 6,000,000 | B7: 0.01 | D7: Ex. 3. What is the cost of all of this? You might think it is 17.52 + 23.36 = $40.88. You would be wrong! You've also lost out on the interest you would have gained on that 17.52 and 23.36. And the compounded interest on that interest. And the compounded interest on the interest of the interest. You get the idea. So what does that actually look like in real numbers?
A8: 6,000,000+ | B8: 0.0075
D10: Scenario 1 | AI10: Scenario 1 | AJ10: WITHOUT AN ADVISOR
D11: Assume I don't invest anything. It just sits there in a cash account. What would be the raw dollar cost of the financial advisor. (i.e. lost opportunity of compounding not realised) | AI11: Assume I don't invest anything. It just sits there in a cash account. What would be the raw dollar cost of the financial advisor. (i.e. lost opportunity of compounding not realised)
D12: Assume I save $5K/mo | AI12: Assume I save $5K/mo
D13: Y1 | E13: Y2 | F13: Y3 | G13: Y4 | H13: Y5 | I13: Y6 | J13: Y7 | K13: Y8 | L13: Y9 | M13: Y10 | N13: Y11 | O13: Y12 | P13: Y13 | Q13: Y14 | R13: Y15 | S13: Y16 | T13: Y17 | U13: Y18 | V13: Y19 | W13: Y20 | X13: Y21 | Y13: Y22 | Z13: Y23 | AA13: Y24 | AB13: Y25 | AC13: Y26 | AD13: Y27 | AE13: Y28 | AI13: Y1 | AJ13: Y2 | AK13: Y3 | AL13: Y4 | AM13: Y5 | AN13: Y6 | AO13: Y7 | AP13: Y8 | AQ13: Y9 | AR13: Y10 | AS13: Y11 | AT13: Y12 | AU13: Y13 | AV13: Y14 | AW13: Y15 | AX13: Y16 | AY13: Y17 | AZ13: Y18 | BA13: Y19 | BB13: Y20 | BC13: Y21 | BD13: Y22 | BE13: Y23 | BF13: Y24 | BG13: Y25 | BH13: Y26 | BI13: Y27 | BJ13: Y28
D14: 0 | AI14: 0
C15: J | D15: =(D14+5000)-(0.00146*(D14+5000)) -> 4992.7 | E15: =(D26+5000)-(0.00146*(D26+5000)) -> 64339.564 | F15: =(E26+5000)-(0.00146*(E26+5000)) -> 122654.98 | G15: =(F26+5000)-(0.00146*(F26+5000)) -> 179956.87 | H15: =(G26+5000)-(0.00146*(G26+5000)) -> 236262.86 | I15: =(H26+5000)-(0.00125*(H26+5000)) -> 292156.94 | J15: =(I26+5000)-(0.00125*(I26+5000)) -> 347319.31 | K15: =(J26+5000)-(0.00125*(J26+5000)) -> 401659.92 | L15: =(K26+5000)-(0.00125*(K26+5000)) -> 455191 | M15: =(L26+5000)-(0.00104*(L26+5000)) -> 508137.17 | N15: =(M26+5000)-(0.00104*(M26+5000)) -> 561427.71 | O15: =(N26+5000)-(0.00104*(N26+5000)) -> 614056.98 | P15: =(O26+5000)-(0.00104*(O26+5000)) -> 666033.17 | Q15: =(P26+5000)-(0.00104*(P26+5000)) -> 717364.4 | R15: =(Q26+5000)-(0.00104*(Q26+5000)) -> 768058.67 | S15: =(R26+5000)-(0.00104*(R26+5000)) -> 818123.88 | T15: =(S26+5000)-(0.00104*(S26+5000)) -> 867567.83 | ... V15: =(U26+5000)-(0.00104*(U26+5000)) -> 964622.73 | W15: =(V26+5000)-(0.000833*(V26+5000)) -> 1013081.9 | X15: =(W26+5000)-(0.000833*(W26+5000)) -> 1062677.5 | Y15: =(X26+5000)-(0.000833*(X26+5000)) -> 1111779.6 | Z15: =(Y26+5000)-(0.000833*(Y26+5000)) -> 1160393.2 | AA15: =(Z26+5000)-(0.000833*(Z26+5000)) -> 1208523 | AB15: =(AA26+5000)-(0.000833*(AA26+5000)) -> 1256173.9 | AC15: =(AB26+5000)-(0.000833*(AB26+5000)) -> 1303350.7 | AD15: =(AC26+5000)-(0.000833*(AC26+5000)) -> 1350058 | AE15: =(AD26+5000)-(0.000833*(AD26+5000)) -> 1396300.6 | AH15: J | AI15: =(AI14+5000)-0 -> 5000 | AJ15: =(AI26+5000)-0 -> 65000 | AK15: =(AJ26+5000)-0 -> 125000 | AL15: =(AK26+5000)-0 -> 185000 | AM15: =(AL26+5000)-0 -> 245000 | AN15: =(AM26+5000)-0 -> 305000 | AO15: =(AN26+5000)-0 -> 365000 | AP15: =(AO26+5000)-0 -> 425000 | AQ15: =(AP26+5000)-0 -> 485000 | ... BJ15: =(BI26+5000)-0 -> 1625000
A16: =0.0175/12 -> 0.0014583333 | B16: 1.75 | C16: F | D16: =(D15+5000)-(0.00146*(D15+5000)) -> 9978.1107 | E16: =(E15+5000)-(0.00146*(E15+5000)) -> 69238.328 | F16: =(F15+5000)-(0.00146*(F15+5000)) -> 127468.6 | G16: =(G15+5000)-(0.00146*(G15+5000)) -> 184686.84 | H16: =(H15+5000)-(0.00146*(H15+5000)) -> 240910.62 | I16: =(I15+5000)-(0.00125*(I15+5000)) -> 296785.49 | J16: =(J15+5000)-(0.00125*(J15+5000)) -> 351878.91 | K16: =(K15+5000)-(0.00125*(K15+5000)) -> 406151.59 | L16: =(L15+5000)-(0.00125*(L15+5000)) -> 459615.76 | M16: =(M15+5000)-(0.00104*(M15+5000)) -> 512603.51 | N16: =(N15+5000)-(0.00104*(N15+5000)) -> 565838.63 | O16: =(O15+5000)-(0.00104*(O15+5000)) -> 618413.16 | P16: =(P15+5000)-(0.00104*(P15+5000)) -> 670335.3 | Q16: =(Q15+5000)-(0.00104*(Q15+5000)) -> 721613.14 | R16: =(R15+5000)-(0.00104*(R15+5000)) -> 772254.69 | S16: =(S15+5000)-(0.00104*(S15+5000)) -> 822267.83 | T16: =(T15+5000)-(0.00104*(T15+5000)) -> 871660.36 | ... V16: =(V15+5000)-(0.00104*(V15+5000)) -> 968614.32 | W16: =(W15+5000)-(0.000833*(W15+5000)) -> 1017233.8 | X16: =(X15+5000)-(0.000833*(X15+5000)) -> 1066788.1 | Y16: =(Y15+5000)-(0.000833*(Y15+5000)) -> 1115849.3 | Z16: =(Z15+5000)-(0.000833*(Z15+5000)) -> 1164422.4 | AA16: =(AA15+5000)-(0.000833*(AA15+5000)) -> 1212512.1 | AB16: =(AB15+5000)-(0.000833*(AB15+5000)) -> 1260123.4 | AC16: =(AC15+5000)-(0.000833*(AC15+5000)) -> 1307260.8 | AD16: =(AD15+5000)-(0.000833*(AD15+5000)) -> 1353929.3 | AE16: =(AE15+5000)-(0.000833*(AE15+5000)) -> 1400133.3 | AH16: F | AI16: =(AI15+5000)-0 -> 10000 | AJ16: =(AJ15+5000)-0 -> 70000 | AK16: =(AK15+5000)-0 -> 130000 | AL16: =(AL15+5000)-0 -> 190000 | AM16: =(AM15+5000)-0 -> 250000 | AN16: =(AN15+5000)-0 -> 310000 | AO16: =(AO15+5000)-0 -> 370000 | AP16: =(AP15+5000)-0 -> 430000 | ... BJ16: =(BJ15+5000)-0 -> 1630000
A17: =0.015/12 -> 0.00125 | B17: 1.5 | C17: M | D17: =(D16+5000)-(0.00146*(D16+5000)) -> 14956.243 | E17: =(E16+5000)-(0.00146*(E16+5000)) -> 74129.94 | F17: =(F16+5000)-(0.00146*(F16+5000)) -> 132275.2 | G17: =(G16+5000)-(0.00146*(G16+5000)) -> 189409.89 | H17: =(H16+5000)-(0.00146*(H16+5000)) -> 245551.59 | I17: =(I16+5000)-(0.00125*(I16+5000)) -> 301408.26 | J17: =(J16+5000)-(0.00125*(J16+5000)) -> 356432.82 | K17: =(K16+5000)-(0.00125*(K16+5000)) -> 410637.66 | L17: =(L16+5000)-(0.00125*(L16+5000)) -> 464034.99 | M17: =(M16+5000)-(0.00104*(M16+5000)) -> 517065.2 | N17: =(N16+5000)-(0.00104*(N16+5000)) -> 570244.96 | O17: =(O16+5000)-(0.00104*(O16+5000)) -> 622764.81 | P17: =(P16+5000)-(0.00104*(P16+5000)) -> 674632.95 | Q17: =(Q16+5000)-(0.00104*(Q16+5000)) -> 725857.46 | R17: =(R16+5000)-(0.00104*(R16+5000)) -> 776446.34 | S17: =(S16+5000)-(0.00104*(S16+5000)) -> 826407.47 | T17: =(T16+5000)-(0.00104*(T16+5000)) -> 875748.64 | ... V17: =(V16+5000)-(0.00104*(V16+5000)) -> 972601.77 | W17: =(W16+5000)-(0.000833*(W16+5000)) -> 1021382.3 | X17: =(X16+5000)-(0.000833*(X16+5000)) -> 1070895.3 | Y17: =(Y16+5000)-(0.000833*(Y16+5000)) -> 1119915.7 | Z17: =(Z16+5000)-(0.000833*(Z16+5000)) -> 1168448.3 | AA17: =(AA16+5000)-(0.000833*(AA16+5000)) -> 1216497.9 | AB17: =(AB16+5000)-(0.000833*(AB16+5000)) -> 1264069.5 | AC17: =(AC16+5000)-(0.000833*(AC16+5000)) -> 1311167.7 | AD17: =(AD16+5000)-(0.000833*(AD16+5000)) -> 1357797.3 | AE17: =(AE16+5000)-(0.000833*(AE16+5000)) -> 1403962.9 | AH17: M | AI17: =(AI16+5000)-0 -> 15000 | AJ17: =(AJ16+5000)-0 -> 75000 | AK17: =(AK16+5000)-0 -> 135000 | AL17: =(AL16+5000)-0 -> 195000 | AM17: =(AM16+5000)-0 -> 255000 | AN17: =(AN16+5000)-0 -> 315000 | AO17: =(AO16+5000)-0 -> 375000 | AP17: =(AP16+5000)-0 -> 435000 | ... BJ17: =(BJ16+5000)-0 -> 1635000
A18: =0.0125/12 -> 0.0010416667 | B18: 1.25 | C18: A | D18: =(D17+5000)-(0.00146*(D17+5000)) -> 19927.107 | E18: =(E17+5000)-(0.00146*(E17+5000)) -> 79014.411 | F18: =(F17+5000)-(0.00146*(F17+5000)) -> 137074.78 | G18: =(G17+5000)-(0.00146*(G17+5000)) -> 194126.06 | H18: =(H17+5000)-(0.00125*(H17+5000)) -> 250238.4 | I18: =(I17+5000)-(0.00125*(I17+5000)) -> 306025.25 | J18: =(J17+5000)-(0.00125*(J17+5000)) -> 360981.02 | K18: =(K17+5000)-(0.00125*(K17+5000)) -> 415118.11 | L18: =(L17+5000)-(0.00125*(L17+5000)) -> 468448.69 | M18: =(M17+5000)-(0.00104*(M17+5000)) -> 521522.26 | N18: =(N17+5000)-(0.00104*(N17+5000)) -> 574646.7 | O18: =(O17+5000)-(0.00104*(O17+5000)) -> 627111.93 | P18: =(P17+5000)-(0.00104*(P17+5000)) -> 678926.13 | Q18: =(Q17+5000)-(0.00104*(Q17+5000)) -> 730097.37 | R18: =(R17+5000)-(0.00104*(R17+5000)) -> 780633.64 | S18: =(S17+5000)-(0.00104*(S17+5000)) -> 830542.81 | T18: =(T17+5000)-(0.00104*(T17+5000)) -> 879832.66 | ... V18: =(V17+5000)-(0.00104*(V17+5000)) -> 976585.06 | W18: =(W17+5000)-(0.000833*(W17+5000)) -> 1025527.3 | X18: =(X17+5000)-(0.000833*(X17+5000)) -> 1074999.1 | Y18: =(Y17+5000)-(0.000833*(Y17+5000)) -> 1123978.6 | Z18: =(Z17+5000)-(0.000833*(Z17+5000)) -> 1172470.8 | AA18: =(AA17+5000)-(0.000833*(AA17+5000)) -> 1220480.4 | AB18: =(AB17+5000)-(0.000833*(AB17+5000)) -> 1268012.4 | AC18: =(AC17+5000)-(0.000833*(AC17+5000)) -> 1315071.3 | AD18: =(AD17+5000)-(0.000833*(AD17+5000)) -> 1361662.1 | AE18: =(AE17+5000)-(0.000833*(AE17+5000)) -> 1407789.2 | AH18: A | AI18: =(AI17+5000)-0 -> 20000 | AJ18: =(AJ17+5000)-0 -> 80000 | AK18: =(AK17+5000)-0 -> 140000 | AL18: =(AL17+5000)-0 -> 200000 | AM18: =(AM17+5000)-0 -> 260000 | AN18: =(AN17+5000)-0 -> 320000 | AO18: =(AO17+5000)-0 -> 380000 | AP18: =(AP17+5000)-0 -> 440000 | ... BJ18: =(BJ17+5000)-0 -> 1640000
A19: =0.01/12 -> 0.00083333333 | B19: 1 | C19: M | D19: =(D18+5000)-(0.00146*(D18+5000)) -> 24890.713 | E19: =(E18+5000)-(0.00146*(E18+5000)) -> 83891.75 | F19: =(F18+5000)-(0.00146*(F18+5000)) -> 141867.35 | G19: =(G18+5000)-(0.00146*(G18+5000)) -> 198835.33 | H19: =(H18+5000)-(0.00125*(H18+5000)) -> 254919.35 | I19: =(I18+5000)-(0.00125*(I18+5000)) -> 310636.47 | J19: =(J18+5000)-(0.00125*(J18+5000)) -> 365523.55 | K19: =(K18+5000)-(0.00125*(K18+5000)) -> 419592.96 | L19: =(L18+5000)-(0.00125*(L18+5000)) -> 472856.88 | M19: =(M18+5000)-(0.00104*(M18+5000)) -> 525974.67 | N19: =(N18+5000)-(0.00104*(N18+5000)) -> 579043.87 | O19: =(O18+5000)-(0.00104*(O18+5000)) -> 631454.54 | P19: =(P18+5000)-(0.00104*(P18+5000)) -> 683214.85 | Q19: =(Q18+5000)-(0.00104*(Q18+5000)) -> 734332.87 | R19: =(R18+5000)-(0.00104*(R18+5000)) -> 784816.58 | S19: =(S18+5000)-(0.00104*(S18+5000)) -> 834673.84 | T19: =(T18+5000)-(0.00104*(T18+5000)) -> 883912.43 | ... V19: =(V18+5000)-(0.00104*(V18+5000)) -> 980564.21 | W19: =(W18+5000)-(0.000833*(W18+5000)) -> 1029668.9 | X19: =(X18+5000)-(0.000833*(X18+5000)) -> 1079099.5 | Y19: =(Y18+5000)-(0.000833*(Y18+5000)) -> 1128038.2 | Z19: =(Z18+5000)-(0.000833*(Z18+5000)) -> 1176489.9 | AA19: =(AA18+5000)-(0.000833*(AA18+5000)) -> 1224459.6 | AB19: =(AB18+5000)-(0.000833*(AB18+5000)) -> 1271951.9 | AC19: =(AC18+5000)-(0.000833*(AC18+5000)) -> 1318971.7 | AD19: =(AD18+5000)-(0.000833*(AD18+5000)) -> 1365523.6 | AE19: =(AE18+5000)-(0.000833*(AE18+5000)) -> 1411612.4 | AH19: M | AI19: =(AI18+5000)-0 -> 25000 | AJ19: =(AJ18+5000)-0 -> 85000 | AK19: =(AK18+5000)-0 -> 145000 | AL19: =(AL18+5000)-0 -> 205000 | AM19: =(AM18+5000)-0 -> 265000 | AN19: =(AN18+5000)-0 -> 325000 | AO19: =(AO18+5000)-0 -> 385000 | AP19: =(AP18+5000)-0 -> 445000 | ... BJ19: =(BJ18+5000)-0 -> 1645000
C20: J | D20: =(D19+5000)-(0.00146*(D19+5000)) -> 29847.072 | E20: =(E19+5000)-(0.00146*(E19+5000)) -> 88761.968 | F20: =(F19+5000)-(0.00146*(F19+5000)) -> 146652.92 | G20: =(G19+5000)-(0.00146*(G19+5000)) -> 203537.73 | H20: =(H19+5000)-(0.00125*(H19+5000)) -> 259594.45 | I20: =(I19+5000)-(0.00125*(I19+5000)) -> 315241.92 | J20: =(J19+5000)-(0.00125*(J19+5000)) -> 370060.39 | K20: =(K19+5000)-(0.00125*(K19+5000)) -> 424062.22 | L20: =(L19+5000)-(0.00125*(L19+5000)) -> 477259.56 | M20: =(M19+5000)-(0.00104*(M19+5000)) -> 530422.46 | N20: =(N19+5000)-(0.00104*(N19+5000)) -> 583436.46 | O20: =(O19+5000)-(0.00104*(O19+5000)) -> 635792.62 | P20: =(P19+5000)-(0.00104*(P19+5000)) -> 687499.1 | Q20: =(Q19+5000)-(0.00104*(Q19+5000)) -> 738563.97 | R20: =(R19+5000)-(0.00104*(R19+5000)) -> 788995.17 | S20: =(S19+5000)-(0.00104*(S19+5000)) -> 838800.58 | T20: =(T19+5000)-(0.00104*(T19+5000)) -> 887987.96 | ... V20: =(V19+5000)-(0.00104*(V19+5000)) -> 984539.22 | W20: =(W19+5000)-(0.000833*(W19+5000)) -> 1033807 | X20: =(X19+5000)-(0.000833*(X19+5000)) -> 1083196.4 | Y20: =(Y19+5000)-(0.000833*(Y19+5000)) -> 1132094.4 | Z20: =(Z19+5000)-(0.000833*(Z19+5000)) -> 1180505.8 | AA20: =(AA19+5000)-(0.000833*(AA19+5000)) -> 1228435.5 | AB20: =(AB19+5000)-(0.000833*(AB19+5000)) -> 1275888.2 | AC20: =(AC19+5000)-(0.000833*(AC19+5000)) -> 1322868.9 | AD20: =(AD19+5000)-(0.000833*(AD19+5000)) -> 1369382 | AE20: =(AE19+5000)-(0.000833*(AE19+5000)) -> 1415432.3 | AH20: J | AI20: =(AI19+5000)-0 -> 30000 | AJ20: =(AJ19+5000)-0 -> 90000 | AK20: =(AK19+5000)-0 -> 150000 | AL20: =(AL19+5000)-0 -> 210000 | AM20: =(AM19+5000)-0 -> 270000 | AN20: =(AN19+5000)-0 -> 330000 | AO20: =(AO19+5000)-0 -> 390000 | AP20: =(AP19+5000)-0 -> 450000 | ... BJ20: =(BJ19+5000)-0 -> 1650000
C21: J | D21: =(D20+5000)-(0.00146*(D20+5000)) -> 34796.196 | E21: =(E20+5000)-(0.00146*(E20+5000)) -> 93625.075 | F21: =(F20+5000)-(0.00146*(F20+5000)) -> 151431.51 | G21: =(G20+5000)-(0.00146*(G20+5000)) -> 208233.27 | H21: =(H20+5000)-(0.00125*(H20+5000)) -> 264263.71 | I21: =(I20+5000)-(0.00125*(I20+5000)) -> 319841.62 | J21: =(J20+5000)-(0.00125*(J20+5000)) -> 374591.57 | K21: =(K20+5000)-(0.00125*(K20+5000)) -> 428525.89 | L21: =(L20+5000)-(0.00125*(L20+5000)) -> 481656.74 | M21: =(M20+5000)-(0.00104*(M20+5000)) -> 534865.62 | N21: =(N20+5000)-(0.00104*(N20+5000)) -> 587824.49 | O21: =(O20+5000)-(0.00104*(O20+5000)) -> 640126.2 | P21: =(P20+5000)-(0.00104*(P20+5000)) -> 691778.9 | Q21: =(Q20+5000)-(0.00104*(Q20+5000)) -> 742790.66 | R21: =(R20+5000)-(0.00104*(R20+5000)) -> 793169.42 | S21: =(S20+5000)-(0.00104*(S20+5000)) -> 842923.03 | T21: =(T20+5000)-(0.00104*(T20+5000)) -> 892059.26 | ... V21: =(V20+5000)-(0.00104*(V20+5000)) -> 988510.1 | W21: =(W20+5000)-(0.000833*(W20+5000)) -> 1037941.7 | X21: =(X20+5000)-(0.000833*(X20+5000)) -> 1087289.9 | Y21: =(Y20+5000)-(0.000833*(Y20+5000)) -> 1136147.2 | Z21: =(Z20+5000)-(0.000833*(Z20+5000)) -> 1184518.2 | AA21: =(AA20+5000)-(0.000833*(AA20+5000)) -> 1232408 | AB21: =(AB20+5000)-(0.000833*(AB20+5000)) -> 1279821.3 | AC21: =(AC20+5000)-(0.000833*(AC20+5000)) -> 1326762.7 | AD21: =(AD20+5000)-(0.000833*(AD20+5000)) -> 1373237.1 | AE21: =(AE20+5000)-(0.000833*(AE20+5000)) -> 1419249.1 | AH21: J | AI21: =(AI20+5000)-0 -> 35000 | AJ21: =(AJ20+5000)-0 -> 95000 | AK21: =(AK20+5000)-0 -> 155000 | AL21: =(AL20+5000)-0 -> 215000 | AM21: =(AM20+5000)-0 -> 275000 | AN21: =(AN20+5000)-0 -> 335000 | AO21: =(AO20+5000)-0 -> 395000 | AP21: =(AP20+5000)-0 -> 455000 | ... BJ21: =(BJ20+5000)-0 -> 1655000
C22: A | D22: =(D21+5000)-(0.00146*(D21+5000)) -> 39738.093 | E22: =(E21+5000)-(0.00146*(E21+5000)) -> 98481.082 | F22: =(F21+5000)-(0.00146*(F21+5000)) -> 156203.12 | G22: =(G21+5000)-(0.00146*(G21+5000)) -> 212921.95 | H22: =(H21+5000)-(0.00125*(H21+5000)) -> 268927.13 | I22: =(I21+5000)-(0.00125*(I21+5000)) -> 324435.57 | J22: =(J21+5000)-(0.00125*(J21+5000)) -> 379117.08 | K22: =(K21+5000)-(0.00125*(K21+5000)) -> 432983.98 | L22: =(L21+5000)-(0.00125*(L21+5000)) -> 486048.42 | M22: =(M21+5000)-(0.00104*(M21+5000)) -> 539304.16 | N22: =(N21+5000)-(0.00104*(N21+5000)) -> 592207.95 | O22: =(O21+5000)-(0.00104*(O21+5000)) -> 644455.27 | P22: =(P21+5000)-(0.00104*(P21+5000)) -> 696054.25 | Q22: =(Q21+5000)-(0.00104*(Q21+5000)) -> 747012.96 | R22: =(R21+5000)-(0.00104*(R21+5000)) -> 797339.32 | S22: =(S21+5000)-(0.00104*(S21+5000)) -> 847041.19 | T22: =(T21+5000)-(0.00104*(T21+5000)) -> 896126.31 | ... V22: =(V21+5000)-(0.00104*(V21+5000)) -> 992476.85 | W22: =(W21+5000)-(0.000833*(W21+5000)) -> 1042072.9 | X22: =(X21+5000)-(0.000833*(X21+5000)) -> 1091380.1 | Y22: =(Y21+5000)-(0.000833*(Y21+5000)) -> 1140196.6 | Z22: =(Z21+5000)-(0.000833*(Z21+5000)) -> 1188527.4 | AA22: =(AA21+5000)-(0.000833*(AA21+5000)) -> 1236377.3 | AB22: =(AB21+5000)-(0.000833*(AB21+5000)) -> 1283751 | AC22: =(AC21+5000)-(0.000833*(AC21+5000)) -> 1330653.4 | AD22: =(AD21+5000)-(0.000833*(AD21+5000)) -> 1377089.1 | AE22: =(AE21+5000)-(0.000833*(AE21+5000)) -> 1423062.7 | AH22: A | AI22: =(AI21+5000)-0 -> 40000 | AJ22: =(AJ21+5000)-0 -> 100000 | AK22: =(AK21+5000)-0 -> 160000 | AL22: =(AL21+5000)-0 -> 220000 | AM22: =(AM21+5000)-0 -> 280000 | AN22: =(AN21+5000)-0 -> 340000 | AO22: =(AO21+5000)-0 -> 400000 | AP22: =(AP21+5000)-0 -> 460000 | ... BJ22: =(BJ21+5000)-0 -> 1660000
C23: S | D23: =(D22+5000)-(0.00146*(D22+5000)) -> 44672.776 | E23: =(E22+5000)-(0.00146*(E22+5000)) -> 103330 | F23: =(F22+5000)-(0.00146*(F22+5000)) -> 160967.76 | G23: =(G22+5000)-(0.00146*(G22+5000)) -> 217603.78 | H23: =(H22+5000)-(0.00125*(H22+5000)) -> 273584.72 | I23: =(I22+5000)-(0.00125*(I22+5000)) -> 329023.77 | J23: =(J22+5000)-(0.00125*(J22+5000)) -> 383636.93 | K23: =(K22+5000)-(0.00125*(K22+5000)) -> 437436.5 | L23: =(L22+5000)-(0.00125*(L22+5000)) -> 490434.61 | M23: =(M22+5000)-(0.00104*(M22+5000)) -> 543738.08 | N23: =(N22+5000)-(0.00104*(N22+5000)) -> 596586.86 | O23: =(O22+5000)-(0.00104*(O22+5000)) -> 648779.83 | P23: =(P22+5000)-(0.00104*(P22+5000)) -> 700325.16 | Q23: =(Q22+5000)-(0.00104*(Q22+5000)) -> 751230.86 | R23: =(R22+5000)-(0.00104*(R22+5000)) -> 801504.89 | S23: =(S22+5000)-(0.00104*(S22+5000)) -> 851155.07 | T23: =(T22+5000)-(0.00104*(T22+5000)) -> 900189.14 | ... V23: =(V22+5000)-(0.00104*(V22+5000)) -> 996439.48 | W23: =(W22+5000)-(0.000833*(W22+5000)) -> 1046200.7 | X23: =(X22+5000)-(0.000833*(X22+5000)) -> 1095466.8 | Y23: =(Y22+5000)-(0.000833*(Y22+5000)) -> 1144242.6 | Z23: =(Z22+5000)-(0.000833*(Z22+5000)) -> 1192533.2 | AA23: =(AA22+5000)-(0.000833*(AA22+5000)) -> 1240343.2 | AB23: =(AB22+5000)-(0.000833*(AB22+5000)) -> 1287677.5 | AC23: =(AC22+5000)-(0.000833*(AC22+5000)) -> 1334540.8 | AD23: =(AD22+5000)-(0.000833*(AD22+5000)) -> 1380937.8 | AE23: =(AE22+5000)-(0.000833*(AE22+5000)) -> 1426873.1 | AH23: S | AI23: =(AI22+5000)-0 -> 45000 | AJ23: =(AJ22+5000)-0 -> 105000 | AK23: =(AK22+5000)-0 -> 165000 | AL23: =(AL22+5000)-0 -> 225000 | AM23: =(AM22+5000)-0 -> 285000 | AN23: =(AN22+5000)-0 -> 345000 | AO23: =(AO22+5000)-0 -> 405000 | AP23: =(AP22+5000)-0 -> 465000 | ... BJ23: =(BJ22+5000)-0 -> 1665000
C24: O | D24: =(D23+5000)-(0.00146*(D23+5000)) -> 49600.253 | E24: =(E23+5000)-(0.00146*(E23+5000)) -> 108171.84 | F24: =(F23+5000)-(0.00146*(F23+5000)) -> 165725.45 | G24: =(G23+5000)-(0.00146*(G23+5000)) -> 222278.78 | H24: =(H23+5000)-(0.00125*(H23+5000)) -> 278236.49 | I24: =(I23+5000)-(0.00125*(I23+5000)) -> 333606.24 | J24: =(J23+5000)-(0.00125*(J23+5000)) -> 388151.14 | K24: =(K23+5000)-(0.00125*(K23+5000)) -> 441883.46 | L24: =(L23+5000)-(0.00125*(L23+5000)) -> 494815.31 | M24: =(M23+5000)-(0.00104*(M23+5000)) -> 548167.4 | N24: =(N23+5000)-(0.00104*(N23+5000)) -> 600961.2 | O24: =(O23+5000)-(0.00104*(O23+5000)) -> 653099.9 | P24: =(P23+5000)-(0.00104*(P23+5000)) -> 704591.62 | Q24: =(Q23+5000)-(0.00104*(Q23+5000)) -> 755444.38 | R24: =(R23+5000)-(0.00104*(R23+5000)) -> 805666.12 | S24: =(S23+5000)-(0.00104*(S23+5000)) -> 855264.66 | T24: =(T23+5000)-(0.00104*(T23+5000)) -> 904247.75 | U24: =(U23+5000)-(0.00104*(U23+5000)) -> 952623 | V24: =(V23+5000)-(0.000833*(V23+5000)) -> 1000605.3 | W24: =(W23+5000)-(0.000833*(W23+5000)) -> 1050325 | X24: =(X23+5000)-(0.000833*(X23+5000)) -> 1099550.1 | Y24: =(Y23+5000)-(0.000833*(Y23+5000)) -> 1148285.3 | Z24: =(Z23+5000)-(0.000833*(Z23+5000)) -> 1196535.6 | AA24: =(AA23+5000)-(0.000833*(AA23+5000)) -> 1244305.8 | AB24: =(AB23+5000)-(0.000833*(AB23+5000)) -> 1291600.7 | AC24: =(AC23+5000)-(0.000833*(AC23+5000)) -> 1338424.9 | ... AE24: =(AE23+5000)-(0.000833*(AE23+5000)) -> 1430680.4 | AH24: O | AI24: =(AI23+5000)-0 -> 50000 | AJ24: =(AJ23+5000)-0 -> 110000 | AK24: =(AK23+5000)-0 -> 170000 | AL24: =(AL23+5000)-0 -> 230000 | AM24: =(AM23+5000)-0 -> 290000 | AN24: =(AN23+5000)-0 -> 350000 | AO24: =(AO23+5000)-0 -> 410000 | AP24: =(AP23+5000)-0 -> 470000 | ... BJ24: =(BJ23+5000)-0 -> 1670000
C25: N | D25: =(D24+5000)-(0.00146*(D24+5000)) -> 54520.537 | E25: =(E24+5000)-(0.00146*(E24+5000)) -> 113006.61 | F25: =(F24+5000)-(0.00146*(F24+5000)) -> 170476.19 | G25: =(G24+5000)-(0.00146*(G24+5000)) -> 226946.95 | H25: =(H24+5000)-(0.00125*(H24+5000)) -> 282882.44 | I25: =(I24+5000)-(0.00125*(I24+5000)) -> 338182.98 | J25: =(J24+5000)-(0.00125*(J24+5000)) -> 392659.7 | K25: =(K24+5000)-(0.00125*(K24+5000)) -> 446324.85 | L25: =(L24+5000)-(0.00125*(L24+5000)) -> 499190.54 | M25: =(M24+5000)-(0.00104*(M24+5000)) -> 552592.1 | N25: =(N24+5000)-(0.00104*(N24+5000)) -> 605331.01 | O25: =(O24+5000)-(0.00104*(O24+5000)) -> 657415.48 | P25: =(P24+5000)-(0.00104*(P24+5000)) -> 708853.64 | Q25: =(Q24+5000)-(0.00104*(Q24+5000)) -> 759653.52 | R25: =(R24+5000)-(0.00104*(R24+5000)) -> 809823.03 | S25: =(S24+5000)-(0.00104*(S24+5000)) -> 859369.99 | T25: =(T24+5000)-(0.00104*(T24+5000)) -> 908302.13 | U25: =(U24+5000)-(0.00104*(U24+5000)) -> 956627.08 | V25: =(V24+5000)-(0.000833*(V24+5000)) -> 1004767.6 | W25: =(W24+5000)-(0.000833*(W24+5000)) -> 1054446 | X25: =(X24+5000)-(0.000833*(X24+5000)) -> 1103630 | Y25: =(Y24+5000)-(0.000833*(Y24+5000)) -> 1152324.6 | Z25: =(Z24+5000)-(0.000833*(Z24+5000)) -> 1200534.7 | AA25: =(AA24+5000)-(0.000833*(AA24+5000)) -> 1248265.1 | AB25: =(AB24+5000)-(0.000833*(AB24+5000)) -> 1295520.6 | AC25: =(AC24+5000)-(0.000833*(AC24+5000)) -> 1342305.9 | ... AE25: =(AE24+5000)-(0.000833*(AE24+5000)) -> 1434484.4 | AH25: N | AI25: =(AI24+5000)-0 -> 55000 | AJ25: =(AJ24+5000)-0 -> 115000 | AK25: =(AK24+5000)-0 -> 175000 | AL25: =(AL24+5000)-0 -> 235000 | AM25: =(AM24+5000)-0 -> 295000 | AN25: =(AN24+5000)-0 -> 355000 | AO25: =(AO24+5000)-0 -> 415000 | AP25: =(AP24+5000)-0 -> 475000 | ... BJ25: =(BJ24+5000)-0 -> 1675000
C26: D | D26: =(D25+5000)-(0.00146*(D25+5000)) -> 59433.637 | E26: =(E25+5000)-(0.00146*(E25+5000)) -> 117834.32 | F26: =(F25+5000)-(0.00146*(F25+5000)) -> 175219.99 | G26: =(G25+5000)-(0.00146*(G25+5000)) -> 231608.31 | H26: =(H25+5000)-(0.00125*(H25+5000)) -> 287522.59 | I26: =(I25+5000)-(0.00125*(I25+5000)) -> 342754.01 | J26: =(J25+5000)-(0.00125*(J25+5000)) -> 397162.62 | K26: =(K25+5000)-(0.00125*(K25+5000)) -> 450760.7 | L26: =(L25+5000)-(0.00104*(L25+5000)) -> 503666.19 | M26: =(M25+5000)-(0.00104*(M25+5000)) -> 557012.21 | N26: =(N25+5000)-(0.00104*(N25+5000)) -> 609696.26 | O26: =(O25+5000)-(0.00104*(O25+5000)) -> 661726.57 | P26: =(P25+5000)-(0.00104*(P25+5000)) -> 713111.24 | Q26: =(Q25+5000)-(0.00104*(Q25+5000)) -> 763858.28 | R26: =(R25+5000)-(0.00104*(R25+5000)) -> 813975.61 | S26: =(S25+5000)-(0.00104*(S25+5000)) -> 863471.04 | ... U26: =(U25+5000)-(0.00104*(U25+5000)) -> 960626.98 | V26: =(V25+5000)-(0.000833*(V25+5000)) -> 1008926.5 | W26: =(W25+5000)-(0.000833*(W25+5000)) -> 1058563.4 | X26: =(X25+5000)-(0.000833*(X25+5000)) -> 1107706.5 | Y26: =(Y25+5000)-(0.000833*(Y25+5000)) -> 1156360.6 | Z26: =(Z25+5000)-(0.000833*(Z25+5000)) -> 1204530.5 | AA26: =(AA25+5000)-(0.000833*(AA25+5000)) -> 1252221.2 | AB26: =(AB25+5000)-(0.000833*(AB25+5000)) -> 1299437.3 | AC26: =(AC25+5000)-(0.000833*(AC25+5000)) -> 1346183.6 | ... AE26: =(AE25+5000)-(0.000833*(AE25+5000)) -> 1438285.4 | AH26: D | AI26: =(AI25+5000)-0 -> 60000 | AJ26: =(AJ25+5000)-0 -> 120000 | AK26: =(AK25+5000)-0 -> 180000 | AL26: =(AL25+5000)-0 -> 240000 | AM26: =(AM25+5000)-0 -> 300000 | AN26: =(AN25+5000)-0 -> 360000 | AO26: =(AO25+5000)-0 -> 420000 | AP26: =(AP25+5000)-0 -> 480000 | ... BJ26: =(BJ25+5000)-0 -> 1680000
AA28: After saving $5K/mo x 25 yrs you should have: | AB28: =5000*12*25 -> 1500000 | BF28: After saving $5K/mo x 25 yrs you should have: | BG28: =6000*12*25 -> 1800000
AA29: You actually have: | AB29: =AF26 -> 0 | BF29: You actually have: | BG29: =BK26 -> 0
AA30: Your advisor cost you: | AB30: =AB28-AB29 -> 1500000 | BF30: Your advisor cost you: | BG30: =BG28-BG29 -> 1800000
AA31: Avg cost/year: | AB31: =AB30/12 -> 125000 | BF31: Because you are your own advisor! | BG31: =BG30/12 -> 150000
D32: Scenario 2 | AI32: Scenario 2 | AJ32: WITHOUT AN ADVISOR
D33: Assume 4% annual return on investments | AI33: Assume 4% annual return on investments
D34: Assume 5K/mo invested | AI34: Assume 5K/mo invested
